Workbook

Sheet pds
A1: nom | B1: prenom | C1: spe | D1: uga | E1: etablissement | F1: adresse | G1: cp | H1: ville | I1: tel | J1: pot | K1: pvm | L1: nv2022 | M1: mode | N1: commentaire | O1: lun mat | P1: lun am | Q1: mar mat | R1: mar am | S1: mer mat | T1: mer am | U1: jeu mat | V1: jeu am | W1: ven mat | X1: ven am | Y1: ddv | Z1: dpv | AA1: ciblage | AB1: rdv | AC1: decile | AD1: reception | AE1: pk
A2: PEYNEAU PONS | B2: Cecile | C2: PSY | D2: 75AUT | F2: 102 RUE BOILEAU | G2: 75016 | H2: PARIS | I2: ` | J2: 68 | K2: 1 | AC2: NP
A3: BALYELI | B3: Filiz | C3: MG | D3: 75AUT | F3: 104 RUE MICHEL ANGE | G3: 75016 | H3: PARIS | J3: 215 | K3: 1
A4: ELY | B4: Chantal | C4: MG | D4: 75AUT | F4: 106 RUE JEAN DE LA FONTAINE | G4: 75016 | H4: PARIS | I4: 145252064 | J4: 234 | K4: 1
A5: LOBBE | B5: Marion | C5: MG | D5: 75AUT | E5: HÔP STE-PÉRINE | F5: 11 RUE CHARDON LAGACHE | G5: 75016 | H5: PARIS | I5: 144963266 | J5: 342 | K5: 1
A6: DE WITASSE THEZY | B6: Albane | C6: MG | D6: 75AUT | E6: HÔP STE-PÉRINE | F6: 11 RUE CHARDON LAGACHE | G6: 75016 | H6: PARIS | I6: 144963176 | J6: 159 | K6: 4
A7: GOURDON | B7: Mathilde | C7: MG | D7: 75AUT | E7: HÔP STE-PÉRINE | F7: 11 RUE CHARDON LAGACHE | G7: 75016 | H7: PARIS | J7: 147 | K7: 1
A8: DEPARIS | B8: Francois | C8: MG | D8: 75AUT | E8: HÔP STE-PÉRINE | F8: 11 RUE CHARDON LAGACHE | G8: 75016 | H8: PARIS | I8: 144963217 | J8: 144 | K8: 1
A9: VYTHILINGUM | B9: Dany | C9: MG | D9: 75AUT | E9: HÔP STE-PÉRINE | F9: 11 RUE CHARDON LAGACHE | G9: 75016 | H9: PARIS | I9: 144963285 | J9: 143 | K9: 2
A10: ABIADH | B10: Hasna | C10: MG | D10: 75AUT | E10: HÔP STE-PÉRINE | F10: 11 RUE CHARDON LAGACHE | G10: 75016 | H10: PARIS | I10: 144963290 | J10: 142 | K10: 1
A11: ASSELIN MULLER DE SCHONGOR | B11: Florence | C11: MG | D11: 75AUT | E11: HÔP STE-PÉRINE | F11: 11 RUE CHARDON LAGACHE | G11: 75016 | H11: PARIS | I11: 144963266 | J11: 142 | K11: 2
A12: BRACHAT | B12: Joelle | C12: MG | D12: 75AUT | E12: HÔP STE-PÉRINE | F12: 11 RUE CHARDON LAGACHE | G12: 75016 | H12: PARIS | I12: 144963217 | J12: 142 | K12: 1
A13: GOMAS | B13: Jean Marie | C13: MG | D13: 75AUT | E13: HÔP STE-PÉRINE | F13: 11 RUE CHARDON LAGACHE | G13: 75016 | H13: PARIS | J13: 142 | K13: 1
A14: LE CRANE | B14: Marine | C14: MG | D14: 75AUT | E14: HÔP STE-PÉRINE | F14: 11 RUE CHARDON LAGACHE | G14: 75016 | H14: PARIS | I14: 144963266 | J14: 142 | K14: 4
A15: PENG | B15: Chang Li | C15: MG | D15: 75AUT | E15: HÔP STE-PÉRINE | F15: 11 RUE CHARDON LAGACHE | G15: 75016 | H15: PARIS | I15: 144963323 | J15: 142 | K15: 1
A16: TARDIVEL | B16: Marie | C16: MG | D16: 75AUT | E16: HÔP STE-PÉRINE | F16: 11 RUE CHARDON LAGACHE | G16: 75016 | H16: PARIS | I16: 144963266 | J16: 142 | K16: 1
A17: BOUJDAY CHRIAA | B17: Lobna | C17: MG | D17: 75AUT | E17: HÔP STE-PÉRINE | F17: 11 RUE CHARDON LAGACHE | G17: 75016 | H17: PARIS | I17: 144963176 | J17: 137 | K17: 1
A18: DE BOUTINY | B18: Servane | C18: MG | D18: 75AUT | E18: HÔP STE-PÉRINE | F18: 11 RUE CHARDON LAGACHE | G18: 75016 | H18: PARIS | I18: 144963154 | J18: 137 | K18: 1
A19: MAHIEUX LAURENT | B19: Florence | C19: NE | D19: 75AUT | E19: HÔP STE-PÉRINE | F19: 11 RUE CHARDON LAGACHE | G19: 75016 | H19: PARIS | I19: 144963217 | J19: 332 | K19: 1
A20: DIARD DETOEUF | B20: Capucine | C20: NE | D20: 75AUT | E20: HÔP STE-PÉRINE | F20: 11 RUE CHARDON LAGACHE | G20: 75016 | H20: PARIS | I20: 144963217 | J20: 190 | K20: 1
A21: SAAL BOURENANE | B21: Fella | C21: MG | D21: 75AUT | F21: 11 RUE DE LA SOURCE | G21: 75016 | H21: PARIS | I21: 155742700 | J21: 178 | K21: 1
A22: BELIERES | B22: Charles | C22: MG | D22: 75AUT | E22: MDS MARY JACOBI | F22: 11 RUE DE VARIZE | G22: 75016 | H22: PARIS | I22: 145271533 | J22: 400 | K22: 3
A23: COMBASTET | B23: Philippe | C23: MG | D23: 75AUT | E23: MDS MARY JACOBI | F23: 11 RUE DE VARIZE | G23: 75016 | H23: PARIS | I23: 145271533 | J23: 346 | K23: 4 | Y23: 45198.458
A24: ECLANCHER | B24: William | C24: MG | D24: 75AUT | E24: MDS MARY JACOBI | F24: 11 RUE DE VARIZE | G24: 75016 | H24: PARIS | I24: 145271533 | J24: 326 | K24: 3 | Y24: 45194.396
A25: HADDAD | B25: Audrey | C25: MG | D25: 75AUT | E25: MDS MARY JACOBI | F25: 11 RUE DE VARIZE | G25: 75016 | H25: PARIS | I25: 145271533 | J25: 266 | K25: 5 | Y25: 45197.583
A26: SCHILDT | B26: Pauline | C26: MG | D26: 75AUT | E26: MDS MARY JACOBI | F26: 11 RUE DE VARIZE | G26: 75016 | H26: PARIS | I26: 145271533 | J26: 211 | K26: 5 | Y26: 45197.417
A27: CHEZAUD | B27: Gabriel | C27: MG | D27: 75AUT | E27: MDS MARY JACOBI | F27: 11 RUE DE VARIZE | G27: 75016 | H27: PARIS | I27: 145271533 | J27: 69 | K27: 1 | Y27: 45199.417
A28: PAUWELS | B28: Mathilde | C28: MG | D28: 75AUT | E28: MDS MARY JACOBI | F28: 11 RUE DE VARIZE | G28: 75016 | H28: PARIS | I28: 145271533 | J28: 0 | K28: 2
A29: ENEAU | B29: Maud | C29: SF | D29: 75AUT | E29: MDS MARY JACOBI | F29: 11 RUE DE VARIZE | G29: 75016 | H29: PARIS | I29: 145271533 | L29: 1 | N29: NPAI
A30: LATOUR DE MAREUIL | B30: Elisabeth | C30: SF | D30: 75AUT | E30: MDS MARY JACOBI | F30: 11 RUE DE VARIZE | G30: 75016 | H30: PARIS | I30: 145271533 | L30: 2 | S30: ok | Y30: 45105.625
A31: LECENDREUX | B31: Michel | C31: PSY | D31: 75AUT | F31: 11 RUE DES PERCHAMPS | G31: 75016 | H31: PARIS | I31: 142151575 | J31: 43 | K31: 1 | L31: 1 | AC31: D1-D4 | AD31: NON | AE31: NRP
A32: HORREARD | B32: Anne Sophie | C32: PE-PSY | D32: 75AUT | F32: 11 RUE DU GENERAL NIOX | G32: 75016 | H32: PARIS | I32: 145656124 | J32: 30 | K32: 1
A33: LEGRAIN | B33: Yann | C33: MG | D33: 75AUT | F33: 114 AVENUE MOZART | G33: 75016 | H33: PARIS | I33: 145250882 | J33: 249 | K33: 8 | N33: NRP? | Y33: 45126.396
A34: CHAUVEL | B34: Yvon | C34: PE | D34: 75AUT | F34: 116 AVENUE DE VERSAILLES | G34: 75016 | H34: PARIS | I34: 142882925 | J34: 103 | K34: 1
A35: ST MARD | B35: Genevieve | C35: PSY | D35: 75AUT | F35: 119 RUE DE LA POMPE | G35: 75016 | H35: PARIS | I35: 147273390 | J35: 51 | K35: 1 | L35: 1
A36: RENARD | B36: Marie Christine | C36: MG | D36: 75AUT | F36: 13 AVENUE DU MARECHAL FRANCHET D ESPEREY | G36: 75016 | H36: PARIS | I36: 140508242 | J36: 212 | K36: 0
A37: DJIAN | B37: Yves | C37: MG | D37: 75AUT | F37: 130 BOULEVARD EXELMANS | G37: 75016 | H37: PARIS | J37: 293 | K37: 1
A38: SOUSSY | B38: Nicolas | C38: MG | D38: 75AUT | F38: 130 BOULEVARD EXELMANS | G38: 75016 | H38: PARIS | I38: 987367775
A39: AZOULAY | B39: Philippe | C39: MG | D39: 75AUT | F39: 133 RUE MICHEL ANGE | G39: 75016 | H39: PARIS | I39: 146201716 | J39: 215 | K39: 2
A40: ROURE | B40: Sabine | C40: GY | D40: 75AUT | F40: 136 BOULEVARD EXELMANS | G40: 75016 | H40: PARIS | I40: 140719502 | J40: 222 | K40: 1
...

Sheet pharma
A1: CIP | B1: NOM | E1: UGA | F1: adresse | G1: cp | H1: ville | I1: tel | K1: CIB. DP | L1: CIB. DSO | M1: NV2022 | N1: DDV | O1: RDV | P1: CA CIRCADIN CMA Fev.23 | Q1: RANG CA CIRCADIN | R1: CA UL CMA Fev.23 | S1: RANG CA UL | T1: CA CIRCADIN CMA Juin.23 | U1: RANG CA CIRCADIN | V1: CA UL CMA Juin.23 | W1: RANG CA UL | X1: DEC. 2023 | Y1: GROUPEMENT | Z1: CONTRAT 2023
A2: 2053775 | B2: PHARMACIE PONSARD | E2: 75PAS | F2: 4 CHAUSSEE DE LA MUETTE | G2: 75016 | H2: PARIS | I2: 142881830 | P2: 3534.55 | Q2: =RANK(P2,P$2:P$404) -> 1 | R2: 1539.62 | S2: 102 | T2: 1895.5 | U2: =RANK($T2,$T$2:$T$121) -> 8 | V2: 783.03 | X2: 5 | Z2: CA<7500 PARTENAIRE
A3: 2003735 | B3: PHARMACIE ZANEA | E3: 75GRE | F3: 13 RUE DU COMMERCE | G3: 75015 | H3: PARIS | I3: 145753335 | K3: 1 | L3: 1 | P3: 2241.16 | Q3: =RANK(P3,P$2:P$404) -> 2 | R3: 4893.61 | S3: 3 | T3: 1226.5 | U3: =RANK($T3,$T$2:$T$121) -> 27 | V3: 5015.49 | W3: 5 | X3: 1 | Y3: APOTHICAL
A4: 2192507 | B4: PHARMACIE BROVILLE | E4: 75GRE | F4: 47 RUE BALARD | G4: 75015 | H4: PARIS | I4: 145579751 | K4: 1 | M4: 2 | N4: 44701 | P4: 1984.7 | Q4: =RANK(P4,P$2:P$404) -> 3 | R4: 2298.45 | S4: 45 | T4: 2943.6 | U4: =RANK($T4,$T$2:$T$121) -> 1 | V4: 2734.51 | W4: 24 | X4: 5 | Y4: IPHARM
A5: 2192690 | B5: PHARMACIE SEGUIN | E5: 75PAS | F5: 141 RUE DE LA TOUR | G5: 75116 | H5: PARIS | I5: 145043233 | K5: 1 | L5: 1 | M5: 1 | N5: 44711 | P5: 1979.13 | Q5: =RANK(P5,P$2:P$404) -> 4 | R5: 3652.13 | S5: 14 | T5: 2040.46 | U5: =RANK($T5,$T$2:$T$121) -> 4 | V5: 3319.85 | W5: 15 | X5: 2 | Z5: CA>7500 STAR PLUS COOP
A6: 2001115 | B6: PHARMACIE ZANA | E6: 75GRE | F6: 55 AVENUE DE SUFFREN | G6: 75007 | H6: PARIS | I6: 147345007 | K6: 1 | P6: 1973.55 | Q6: =RANK(P6,P$2:P$404) -> 5 | R6: 1669.14 | S6: 90 | T6: 1527.55 | U6: =RANK($T6,$T$2:$T$121) -> 16 | V6: 1589.36 | W6: 103 | X6: 5 | Y6: APRIUM
A7: 2192989 | B7: PHARMACIE DE LA PORTE D AUTEUIL | E7: 75AUT | F7: 52 RUE D AUTEUIL | G7: 75016 | H7: PARIS | I7: 142882738 | K7: 1 | L7: 1 | M7: 2 | N7: 44721 | P7: 1945.68 | Q7: =RANK(P7,P$2:P$404) -> 6 | R7: 2831.5 | S7: 25 | T7: 1817.46 | U7: =RANK($T7,$T$2:$T$121) -> 9 | V7: 2454.76 | W7: 37 | X7: 4 | Y7: APRIUM
A8: 2193060 | B8: PHARMACIE DE LA POMPE | E8: 75PAS | F8: 66 RUE DE LA POMPE | G8: 75116 | H8: PARIS | I8: 145047346 | K8: 1 | L8: 1 | P8: 1901.08 | Q8: =RANK(P8,P$2:P$404) -> 7 | R8: 2428.02 | S8: 41 | T8: 1092.7 | U8: =RANK($T8,$T$2:$T$121) -> 39 | V8: 2555.5 | W8: 29 | X8: 3 | Y8: COS 500
A9: 2193102 | B9: PHARMACIE EXELMANS | E9: 75AUT | F9: 77 BOULEVARD EXELMANS | G9: 75016 | H9: PARIS | I9: 146512392 | K9: 1 | L9: 1 | M9: 2 | N9: 44721 | P9: 1850.9 | Q9: =RANK(P9,P$2:P$404) -> 8 | R9: 4057.55 | S9: 7 | T9: 2202.13 | U9: =RANK($T9,$T$2:$T$121) -> 3 | V9: 3819.86 | W9: 10 | X9: 2 | Y9: CENTRALE DES PHARMACIENS | Z9: CA>7500 PARTENAIRE PLUS
A10: 2192952 | B10: PHARMACIE BAILLY | E10: 75PAS | F10: 48 B AVENUE MOZART | G10: 75016 | H10: PARIS | I10: 142881381 | K10: 1 | P10: 1756.13 | Q10: =RANK(P10,P$2:P$404) -> 9 | R10: 937.78 | T10: 1538.7 | U10: =RANK($T10,$T$2:$T$121) -> 14 | V10: 1257.41 | X10: 7 | Y10: EXCEL PHARMA | Z10: CA<7500 TOP24
A11: 2192334 | B11: PHARMACIE DE L ECOLE DE GUERRE | E11: 75GRE | F11: 57 B AVENUE DE LA MOTTE PICQUET | G11: 75015 | H11: PARIS | I11: 147346204 | K11: 1 | L11: 1 | M11: 2 | N11: 44687 | P11: 1661.35 | Q11: =RANK(P11,P$2:P$404) -> 10 | R11: 2004.35 | S11: 67 | T11: 217.43 | V11: 1708.74 | W11: 90 | X11: 7 | Z11: CA<7500 PARTENAIRE
A12: 2048220 | B12: PHARMACIE DE LONGCHAMPS | E12: 92NEU | F12: 9 B RUE ERNEST DELOISON | G12: 92200 | H12: NEUILLY SUR SEINE | I12: 146247050 | K12: 1 | L12: 1 | P12: 1639.05 | Q12: =RANK(P12,P$2:P$404) -> 11 | R12: 2119.01 | S12: 56 | T12: 1226.5 | U12: =RANK($T12,$T$2:$T$121) -> 27 | V12: 1692 | W12: 94 | X12: 4 | Y12: APRIUM
A13: 2192727 | B13: PHARMACIE DU GARIGLIANO | E13: 75AUT | F13: 167 AVENUE DE VERSAILLES | G13: 75016 | H13: PARIS | I13: 142883337 | K13: 1 | P13: 1639.05 | Q13: =RANK(P13,P$2:P$404) -> 11 | R13: 1777.47 | S13: 77 | T13: 1627.9 | U13: =RANK($T13,$T$2:$T$121) -> 12 | V13: 1280.41 | X13: 7 | Y13: CENTRALE DES PHARMACIENS | Z13: CA<7500 TOP24
A14: 2192774 | B14: PHARMACIE DU MARCHE | E14: 75AUT | F14: 197 AVENUE DE VERSAILLES | G14: 75016 | H14: PARIS | I14: 146516408 | K14: 1 | P14: 1627.9 | Q14: =RANK(P14,P$2:P$404) -> 13 | R14: 1373.3968 | S14: 115 | T14: 1945.68 | U14: =RANK($T14,$T$2:$T$121) -> 6 | V14: 1367.5368 | X14: 7 | Y14: PHARMAZON | Z14: CA<7500 TOP24
A15: 2054061 | B15: PHARMACIE WUHRLIN CHARBONNEL | E15: 75PER | F15: 64 RUE DE TOCQUEVILLE | G15: 75017 | H15: PARIS | I15: 143801340 | K15: 1 | L15: 1 | P15: 1600.03 | Q15: =RANK(P15,P$2:P$404) -> 14 | R15: 1488.56 | S15: 107 | T15: 1103.86 | U15: =RANK($T15,$T$2:$T$121) -> 36 | V15: 1673.97 | W15: 98 | X15: 4 | Y15: APRIUM | Z15: LEADER SANTE/ APRIUM STAR
A16: 2053670 | B16: PHARMACIE AOUIZERAT | E16: 75AUT | F16: 43 RUE D AUTEUIL | G16: 75016 | H16: PARIS | I16: 142880796 | K16: 1 | L16: 1 | M16: 2 | N16: 44679 | P16: 1561 | Q16: =RANK(P16,P$2:P$404) -> 15 | R16: 3749.71 | S16: 11 | T16: 1181.9 | U16: =RANK($T16,$T$2:$T$121) -> 30 | V16: 3433.89 | W16: 13 | X16: 2 | Y16: IPHARM
A17: 2192182 | B17: PHARMACIE LEON | E17: 75GRE | F17: 39 BOULEVARD DE GRENELLE | G17: 75015 | H17: PARIS | I17: 145795319 | K17: 1 | L17: 1 | P17: 1555.43 | Q17: =RANK(P17,P$2:P$404) -> 16 | R17: 985.97 | T17: 1059.26 | U17: =RANK($T17,$T$2:$T$121) -> 43 | V17: 982.56 | X17: 6 | Y17: APRIUM
A18: 2053644 | B18: PHARMACIE DE LA PORTE DE SAINT CLOUD | E18: 75AUT | F18: 122 BOULEVARD MURAT | G18: 75016 | H18: PARIS | I18: 142887416 | K18: 1 | L18: 1 | M18: 2 | N18: 44714 | P18: 1549.85 | Q18: =RANK(P18,P$2:P$404) -> 17 | R18: 4641.72 | S18: 4 | T18: 1945.68 | U18: =RANK($T18,$T$2:$T$121) -> 6 | V18: 5054.19 | W18: 4 | X18: 3 | Y18: ELSIE | Z18: ELSIE VIP
A19: 2228810 | B19: PHARMACIE DE NEUILLY | E19: 92NEU | F19: 43 RUE DE CHARTRES | G19: 92200 | H19: NEUILLY SUR SEINE | I19: 146240324 | K19: 1 | L19: 1 | M19: 2 | N19: 44706 | P19: 1549.85 | Q19: =RANK(P19,P$2:P$404) -> 17 | R19: 3685.78 | S19: 12 | T19: 2235.58 | U19: =RANK($T19,$T$2:$T$121) -> 2 | V19: 4052.57 | W19: 8 | X19: 2 | Y19: APRIUM | Z19: LEADER SANTE/ APRIUM STAR PLUS
A20: 2014048 | B20: PHARMACIE EL KAIM LESELBAUM | E20: 92LEV | F20: 1 PLACE DE LA REPUBLIQUE | G20: 92300 | H20: LEVALLOIS PERRET | I20: 147370326 | P20: 1525.04 | Q20: =RANK(P20,P$2:P$404) -> 19 | R20: 2111.36 | S20: 52 | T20: 1525.04 | U20: =RANK($T20,$T$2:$T$121) -> 17 | V20: 2111.36 | W20: 52 | X20: 5 | Y20: PHARMACTIV | Z20: CA<7500 STAR
A21: 2052106 | B21: PHARMACIE ANGLAISE | E21: 75TER | F21: 62 AVENUE DES CHAMPS ELYSEES | G21: 75008 | H21: PARIS | I21: 143598230 | K21: 1 | L21: 1 | M21: 2 | N21: 44685 | P21: 1482.95 | Q21: =RANK(P21,P$2:P$404) -> 20 | R21: 1954.09 | S21: 71 | T21: 1137.31 | U21: =RANK($T21,$T$2:$T$121) -> 32 | V21: 1863.13 | W21: 72 | X21: 2 | Y21: APRIUM UM
A22: 2053534 | B22: PHARMACIE BOUCICAUT | E22: 75GRE | F22: 45 AVENUE FELIX FAURE | G22: 75015 | H22: PARIS | I22: 145584589 | K22: 1 | P22: 1466.23 | Q22: =RANK(P22,P$2:P$404) -> 21 | R22: 1385.66 | S22: 114 | T22: 852.99 | U22: =RANK($T22,$T$2:$T$121) -> 55 | V22: 1552.23 | W22: 109 | X22: 7 | Y22: SUPRAPHARM | Z22: CA<7500 STAR
A23: 2048304 | B23: PHARMACIE DU PONT DE NEUILLY | E23: 92NEU | F23: 174 AVENUE CHARLES DE GAULLE | G23: 92200 | H23: NEUILLY SUR SEINE | I23: 146247532 | K23: 1 | L23: 1 | P23: 1404.91 | Q23: =RANK(P23,P$2:P$404) -> 22 | R23: 1983.66 | S23: 68 | T23: 1349.17 | U23: =RANK($T23,$T$2:$T$121) -> 23 | V23: 2059.7608 | W23: 58 | X23: 5 | Y23: ALPHEGA DIAMANT | Z23: CA<7500 PARTENAIRE
A24: 2191828 | B24: PHARMACIE LOURMEL | E24: 75GRE | F24: 105 AVENUE FELIX FAURE | G24: 75015 | H24: PARIS | I24: 145574545 | K24: 1 | L24: 1 | M24: 2 | N24: 44652 | P24: 1393.76 | Q24: =RANK(P24,P$2:P$404) -> 23 | R24: 3663.66 | S24: 13 | T24: 652.28 | U24: =RANK($T24,$T$2:$T$121) -> 72 | V24: 2944.39 | W24: 20 | X24: 3 | Y24: APRIUM
A25: 2192910 | B25: PHARMACIE DES BELLES FEUILLES | E25: 75TRO | F25: 37 41 RUE SAINT DIDIER | G25: 75116 | H25: PARIS | I25: 147271472 | K25: 1 | L25: 1 | P25: 1365.88 | Q25: =RANK(P25,P$2:P$404) -> 24 | R25: 1768.7 | S25: 78 | T25: 1131.73 | U25: =RANK($T25,$T$2:$T$121) -> 33 | V25: 1904.09 | W25: 67 | X25: 4 | Y25: LEADER SANTE
A26: 2193495 | B26: PHARMACIE DE LA TERRASSE | E26: 75PER | F26: 35 RUE DE LEVIS | G26: 75017 | H26: PARIS | I26: 147632412 | K26: 1 | L26: 1 | P26: 1237.65 | Q26: =RANK(P26,P$2:P$404) -> 25 | R26: 2851.72 | S26: 24 | T26: 1460.65 | U26: =RANK($T26,$T$2:$T$121) -> 19 | V26: 2485.05 | W26: 33 | X26: 3 | Y26: IPHARM
A27: 2230238 | B27: PHARMACIE DU ROULE | E27: 92NEU | F27: 8 PLACE DU GENERAL GOURAUD | G27: 92200 | H27: NEUILLY SUR SEINE | I27: 146240662 | K27: 1 | L27: 1 | P27: 1193.05 | Q27: =RANK(P27,P$2:P$404) -> 26 | R27: 1665.13 | S27: 91 | T27: 524.05 | U27: =RANK($T27,$T$2:$T$121) -> 94 | V27: 1833.58 | W27: 74 | X27: 5 | Y27: LEADER SANTE
A28: 2260833 | B28: PHARMACIE BOULAINVILLIERS | E28: 75PAS | F28: 48 RUE DE BOULAINVILLIERS | G28: 75016 | H28: PARIS | I28: 142882178 | K28: 1 | P28: 1187.48 | Q28: =RANK(P28,P$2:P$404) -> 27 | R28: 1684.24 | S28: 89 | T28: 836.26 | U28: =RANK($T28,$T$2:$T$121) -> 57 | V28: 1440.02 | W28: 116 | X28: 9 | Y28: CENTRALE DES PHARMACIENS | Z28: CA<7500 STAR
A29: 2192947 | B29: GRANDE PHARMACIE D AUTEUIL | E29: 75AUT | F29: 4 RUE POUSSIN | G29: 75016 | H29: PARIS | I29: 142880771 | K29: 1 | L29: 1 | P29: 1185.25 | Q29: =RANK(P29,P$2:P$404) -> 28 | R29: 1436.83 | S29: 111 | T29: 1612.3 | U29: =RANK($T29,$T$2:$T$121) -> 13 | V29: 1717.33 | W29: 88 | X29: 5 | Y29: PHARMAVIE GOLD | Z29: CA<7500 STAR
A30: 2192968 | B30: PHARMACIE MOREAU | E30: 75TRO | F30: 5 PLACE DE MEXICO | G30: 75116 | H30: PARIS | I30: 147278195 | K30: 1 | P30: 1176.33 | Q30: =RANK(P30,P$2:P$404) -> 29 | R30: 1570.89 | S30: 97 | T30: 1276.69 | U30: =RANK($T30,$T$2:$T$121) -> 25 | V30: 1383.33 | X30: 5 | Z30: CA<7500 TOP24
A31: 2193689 | B31: PHARMACIE DU MARECHAL JUIN | E31: 75PER | F31: 7 PLACE DU MARECHAL JUIN | G31: 75017 | H31: PARIS | I31: 147633439 | K31: 1 | L31: 1 | M31: 2 | N31: 44698 | P31: 1142.88 | Q31: =RANK(P31,P$2:P$404) -> 30 | R31: 4073.76 | S31: 6 | T31: 1154.04 | U31: =RANK($T31,$T$2:$T$121) -> 31 | V31: 4765.64 | W31: 6 | X31: 4 | Y31: APRIUM
A32: 2192596 | B32: PHARMACIE CONSEIL PASSY | E32: 75PAS | F32: 7 RUE DE L ALBONI | G32: 75016 | H32: PARIS | I32: 142882034 | K32: 1 | L32: 1 | P32: 1120.58 | Q32: =RANK(P32,P$2:P$404) -> 31 | R32: 2614.76 | S32: 31 | T32: 1365.89 | U32: =RANK($T32,$T$2:$T$121) -> 22 | V32: 2942.07 | W32: 21 | X32: 3 | Z32: CA<7500 STAR
A33: 2054192 | B33: PHARMACIE SOLARD | E33: 75PER | F33: 106 BOULEVARD DE COURCELLES | G33: 75017 | H33: PARIS | I33: 147634548 | K33: 1 | L33: 1 | M33: 2 | N33: 44714 | P33: 1109.43 | Q33: =RANK(P33,P$2:P$404) -> 32 | R33: 2205.83 | S33: 53 | T33: 1103.86 | U33: =RANK($T33,$T$2:$T$121) -> 36 | V33: 2105.99 | W33: 53 | X33: 6 | Y33: CENTRALE DES PHARMACIENS | Z33: CA<7500 STAR
A34: 2192114 | B34: PHARMACIE DU GRAND PAVOIS | E34: 75GRE | F34: 360 RUE LECOURBE | G34: 75015 | H34: PARIS | I34: 145547983 | K34: 1 | L34: 1 | M34: 2 | N34: 44683 | P34: 1103.85 | Q34: =RANK(P34,P$2:P$404) -> 33 | R34: 2632.45 | S34: 28 | T34: 434.85 | V34: 2279.73 | W34: 44 | X34: 8 | Z34: CA<7500 TOP24
A35: 2053424 | B35: PHARMACIE NECKER | E35: 75MNP | F35: 47 BOULEVARD PASTEUR | G35: 75015 | H35: PARIS | I35: 147836927 | K35: 1 | L35: 1 | M35: 2 | N35: 44692 | P35: 1070.4 | Q35: =RANK(P35,P$2:P$404) -> 34 | R35: 1057.41 | T35: 1382.6 | U35: =RANK($T35,$T$2:$T$121) -> 21 | V35: 789.18 | X35: 7 | Y35: COTE PHARMA
A36: 2053466 | B36: PHARMACIE PHARMAVANCE | E36: 75MNP | F36: 315 RUE DE VAUGIRARD | G36: 75015 | H36: PARIS | I36: 148284585 | K36: 1 | L36: 1 | P36: 1048.1 | Q36: =RANK(P36,P$2:P$404) -> 35 | R36: 2479.93 | S36: 39 | T36: 334.5 | V36: 2251.07 | W36: 47 | X36: 3 | Y36: PHARMAZON | Z36: CA>7500 STAR PLUS COOP
A37: 2192711 | B37: PHARMACIE LITSCHI | E37: 75PAS | F37: 156 AVENUE VICTOR HUGO | G37: 75116 | H37: PARIS | I37: 147276814 | K37: 1 | L37: 1 | P37: 1048.1 | Q37: =RANK(P37,P$2:P$404) -> 35 | R37: 2239.59 | S37: 48 | T37: 1103.86 | U37: =RANK($T37,$T$2:$T$121) -> 36 | V37: 1673.98 | W37: 97 | X37: 5 | Y37: APRIUM
A38: 2192685 | B38: PHARMACIE REMUSAT | E38: 75AUT | F38: 14 RUE DE REMUSAT | G38: 75016 | H38: PARIS | I38: 145251850 | K38: 1 | L38: 1 | P38: 1014.65 | Q38: =RANK(P38,P$2:P$404) -> 37 | R38: 2090.13 | S38: 57 | T38: 1449.51 | U38: =RANK($T38,$T$2:$T$121) -> 20 | V38: 1964.53 | W38: 63 | X38: 6 | Y38: APRIUM
A39: 2053513 | B39: PHARMACIE LECOURBE CAMBRONNE | E39: 75MNP | F39: 112 RUE LECOURBE | G39: 75015 | H39: PARIS | I39: 147340552 | K39: 1 | L39: 1 | P39: 1003.5 | Q39: =RANK(P39,P$2:P$404) -> 38 | R39: 3326.19 | S39: 17 | T39: 914.31 | U39: =RANK($T39,$T$2:$T$121) -> 52 | V39: 2083.99 | W39: 55 | X39: 4 | Z39: CA>7500 STAR PLUS COOP
A40: 2193139 | B40: GRANDE PHARMACIE DOUMER PASSY | E40: 75PAS | F40: 83 AVENUE PAUL DOUMER | G40: 75116 | H40: PARIS | I40: 145252054 | K40: 1 | L40: 1 | M40: 2 | N40: 44735 | P40: 1003.5 | Q40: =RANK(P40,P$2:P$404) -> 38 | R40: 2631.42 | S40: 29 | T40: 669 | U40: =RANK($T40,$T$2:$T$121) -> 69 | V40: 2337.15 | W40: 41 | X40: 2 | Z40: CA<7500 TOP24
...

Sheet recap
D1: CIBLAGE PDS
B3: CATEGORIE | C3: SPE | D3: NB PDS PRESENTS BASE VEEVA | E3: NB PDS CIBLES | F3: TOTAL CONTACTS | G3: OBJECTIFS NB PDS | H3: OBJECTIFS CONTACTS | I3: R/O NB PDS | J3: R/O CONTACTS | M3: SFEM | S3: MG | U3: PEDIATRE | W3: GASTRO
B4: SFEM | C4: Médecine générale-Gyn | D4: 22 | E4: =IFERROR(COUNTIFS(pds!C:C,"MG-GY",pds!AA:AA,">0"),0) -> 19 | F4: =IFERROR(SUMIFS(pds!AA:AA,pds!C:C,"MG-GY",pds!AA:AA,">0"),0) -> 57 | G4: 136 | H4: 401 | I4: =IFERROR(SUM(E4:E6)/G4,0) -> 0.99264706 | J4: =IFERROR(SUM(F4:F6)/H4,0) -> 0.9925187 | M4: Médecine générale-Gyn | O4: Sage-femme | Q4: Gynécologie | S4: Médecine générale | U4: Pédiatrie | W4: Gastro-entérologie
C5: Sage-femme | D5: 12 | E5: =IFERROR(COUNTIFS(pds!C:C,"SF",pds!AA:AA,">0"),0) -> 0 | F5: =IFERROR(SUMIFS(pds!AA:AA,pds!C:C,"SF",pds!AA:AA,">0"),0) -> 0 | L5: ENGAGEMENT | M5: C1 2023 | N5: C2 2023 | O5: C1 2023 | P5: C2 2023 | Q5: C1 2023 | R5: C2 2023 | S5: C1 2023 | T5: C2 2023 | U5: C1 2023 | V5: C2 2023 | W5: C1 2023 | X5: C2 2023 | Y5: C1 2023 | Z5: C2 2023 | AA5: C1 2023 | AB5: C2 2023 | AC5: C1 2023 | AD5: C2 2023
C6: Gynécologie | D6: 330 | E6: =IFERROR(COUNTIFS(pds!C:C,"GY",pds!AA:AA,">0"),0) -> 116 | F6: =IFERROR(SUMIFS(pds!AA:AA,pds!C:C,"GY",pds!AA:AA,">0"),0) -> 341 | L6: 1 | M6: =IFERROR(COUNTIFS(pds!C:C,"Médecine générale",#REF!,"Gyn",#REF!,L6),0) -> 0 | N6: =IFERROR(COUNTIFS(pds!C:C,"Médecine générale",#REF!,"Gyn",#REF!,L6),0) -> 0 | O6: =IFERROR(COUNTIFS(pds!C:C,"Sage-femme",#REF!,L6),0) -> 0 | P6: =IFERROR(COUNTIFS(pds!C:C,"Sage-femme",#REF!,L6),0) -> 0 | Q6: =IFERROR(COUNTIFS(pds!C:C,"Gynécologie",#REF!,L6),0) -> 0 | R6: =IFERROR(COUNTIFS(pds!C:C,"Gynécologie",#REF!,L6),0) -> 0 | S6: =IFERROR(COUNTIFS(pds!C:C,"Médecine générale",#REF!,"<>Gyn",#REF!,L6),0) -> 0 | T6: =IFERROR(COUNTIFS(pds!C:C,"Médecine générale",#REF!,"<>Gyn",#REF!,L6),0) -> 0 | U6: =IFERROR(COUNTIFS(pds!C:C,"Pédiatrie",#REF!,L6),0) -> 0 | V6: =IFERROR(COUNTIFS(pds!C:C,"Pédiatrie",#REF!,L6),0) -> 0 | W6: =IFERROR(COUNTIFS(pds!C:C,"Gastro-entérologie",#REF!,L6),0) -> 0 | X6: =IFERROR(COUNTIFS(pds!C:C,"Gastro-entérologie",#REF!,L6),0) -> 0
B7: MG | C7: Médecine générale | D7: 858 | E7: =IFERROR(COUNTIFS(pds!C:C,"MG",pds!AA:AA,">0"),0) -> 49 | F7: =IFERROR(SUMIFS(pds!AA:AA,pds!C:C,"MG",pds!AA:AA,">0"),0) -> 145 | G7: 49 | H7: 145 | I7: =IFERROR(E7/G7,0) -> 1 | J7: =IFERROR(F7/H7,0) -> 1 | L7: 2 | M7: =IFERROR(COUNTIFS(pds!C:C,"Médecine générale",#REF!,"Gyn",#REF!,L7),0) -> 0 | N7: =IFERROR(COUNTIFS(pds!C:C,"Médecine générale",#REF!,"Gyn",#REF!,L7),0) -> 0 | O7: =IFERROR(COUNTIFS(pds!C:C,"Sage-femme",#REF!,L7),0) -> 0 | P7: =IFERROR(COUNTIFS(pds!C:C,"Sage-femme",#REF!,L7),0) -> 0 | Q7: =IFERROR(COUNTIFS(pds!C:C,"Gynécologie",#REF!,L7),0) -> 0 | R7: =IFERROR(COUNTIFS(pds!C:C,"Gynécologie",#REF!,L7),0) -> 0 | S7: =IFERROR(COUNTIFS(pds!C:C,"Médecine générale",#REF!,"<>Gyn",#REF!,L7),0) -> 0 | T7: =IFERROR(COUNTIFS(pds!C:C,"Médecine générale",#REF!,"<>Gyn",#REF!,L7),0) -> 0 | U7: =IFERROR(COUNTIFS(pds!C:C,"Pédiatrie",#REF!,L7),0) -> 0 | V7: =IFERROR(COUNTIFS(pds!C:C,"Pédiatrie",#REF!,L7),0) -> 0 | W7: =IFERROR(COUNTIFS(pds!C:C,"Gastro-entérologie",#REF!,L7),0) -> 0 | X7: =IFERROR(COUNTIFS(pds!C:C,"Gastro-entérologie",#REF!,L7),0) -> 0
B8: PEDIATRE | C8: Pédiatrie | D8: 317 | E8: =IFERROR(COUNTIFS(pds!C:C,"PE",pds!AA:AA,">0"),0) -> 47 | F8: =IFERROR(SUMIFS(pds!AA:AA,pds!C:C,"PE",pds!AA:AA,">0"),0) -> 139 | G8: 48 | H8: 142 | I8: =IFERROR(E8/G8,0) -> 0.97916667 | J8: =IFERROR(F8/H8,0) -> 0.97887324 | L8: 3 | M8: =IFERROR(COUNTIFS(pds!C:C,"Médecine générale",#REF!,"Gyn",#REF!,L8),0) -> 0 | N8: =IFERROR(COUNTIFS(pds!C:C,"Médecine générale",#REF!,"Gyn",#REF!,L8),0) -> 0 | O8: =IFERROR(COUNTIFS(pds!C:C,"Sage-femme",#REF!,L8),0) -> 0 | P8: =IFERROR(COUNTIFS(pds!C:C,"Sage-femme",#REF!,L8),0) -> 0 | Q8: =IFERROR(COUNTIFS(pds!C:C,"Gynécologie",#REF!,L8),0) -> 0 | R8: =IFERROR(COUNTIFS(pds!C:C,"Gynécologie",#REF!,L8),0) -> 0 | S8: =IFERROR(COUNTIFS(pds!C:C,"Médecine générale",#REF!,"<>Gyn",#REF!,L8),0) -> 0 | T8: =IFERROR(COUNTIFS(pds!C:C,"Médecine générale",#REF!,"<>Gyn",#REF!,L8),0) -> 0 | U8: =IFERROR(COUNTIFS(pds!C:C,"Pédiatrie",#REF!,L8),0) -> 0 | V8: =IFERROR(COUNTIFS(pds!C:C,"Pédiatrie",#REF!,L8),0) -> 0 | W8: =IFERROR(COUNTIFS(pds!C:C,"Gastro-entérologie",#REF!,L8),0) -> 0 | X8: =IFERROR(COUNTIFS(pds!C:C,"Gastro-entérologie",#REF!,L8),0) -> 0
B9: GASTRO | C9: Gastro-entérologie | D9: 105 | E9: =IFERROR(COUNTIFS(pds!C:C,"GE",pds!AA:AA,">0"),0) -> 18 | F9: =IFERROR(SUMIFS(pds!AA:AA,pds!C:C,"GE",pds!AA:AA,">0"),0) -> 52 | G9: 19 | H9: 55 | I9: =IFERROR(E9/G9,0) -> 0.94736842 | J9: =IFERROR(F9/H9,0) -> 0.94545455 | L9: 4 | M9: =IFERROR(COUNTIFS(pds!C:C,"Médecine générale",#REF!,"Gyn",#REF!,L9),0) -> 0 | N9: =IFERROR(COUNTIFS(pds!C:C,"Médecine générale",#REF!,"Gyn",#REF!,L9),0) -> 0 | O9: =IFERROR(COUNTIFS(pds!C:C,"Sage-femme",#REF!,L9),0) -> 0 | P9: =IFERROR(COUNTIFS(pds!C:C,"Sage-femme",#REF!,L9),0) -> 0 | Q9: =IFERROR(COUNTIFS(pds!C:C,"Gynécologie",#REF!,L9),0) -> 0 | R9: =IFERROR(COUNTIFS(pds!C:C,"Gynécologie",#REF!,L9),0) -> 0 | S9: =IFERROR(COUNTIFS(pds!C:C,"Médecine générale",#REF!,"<>Gyn",#REF!,L9),0) -> 0 | T9: =IFERROR(COUNTIFS(pds!C:C,"Médecine générale",#REF!,"<>Gyn",#REF!,L9),0) -> 0 | U9: =IFERROR(COUNTIFS(pds!C:C,"Pédiatrie",#REF!,L9),0) -> 0 | V9: =IFERROR(COUNTIFS(pds!C:C,"Pédiatrie",#REF!,L9),0) -> 0 | W9: =IFERROR(COUNTIFS(pds!C:C,"Gastro-entérologie",#REF!,L9),0) -> 0 | X9: =IFERROR(COUNTIFS(pds!C:C,"Gastro-entérologie",#REF!,L9),0) -> 0
B10: PEDO PSY | C10: Pédopsychiatrie | E10: =IFERROR(COUNTIFS(pds!C:C,"PE-PSY",pds!AA:AA,">0"),0) -> 4 | F10: =IFERROR(SUMIFS(pds!AA:AA,pds!C:C,"PE-PSY",pds!AA:AA,">0"),0) -> 13 | H10: 13 | L10: 5 | M10: =IFERROR(COUNTIFS(pds!C:C,"Médecine générale",#REF!,"Gyn",#REF!,L10),0) -> 0 | N10: =IFERROR(COUNTIFS(pds!C:C,"Médecine générale",#REF!,"Gyn",#REF!,L10),0) -> 0 | O10: =IFERROR(COUNTIFS(pds!C:C,"Sage-femme",#REF!,L10),0) -> 0 | P10: =IFERROR(COUNTIFS(pds!C:C,"Sage-femme",#REF!,L10),0) -> 0 | Q10: =IFERROR(COUNTIFS(pds!C:C,"Gynécologie",#REF!,L10),0) -> 0 | R10: =IFERROR(COUNTIFS(pds!C:C,"Gynécologie",#REF!,L10),0) -> 0 | S10: =IFERROR(COUNTIFS(pds!C:C,"Médecine générale",#REF!,"<>Gyn",#REF!,L10),0) -> 0 | T10: =IFERROR(COUNTIFS(pds!C:C,"Médecine générale",#REF!,"<>Gyn",#REF!,L10),0) -> 0 | U10: =IFERROR(COUNTIFS(pds!C:C,"Pédiatrie",#REF!,L10),0) -> 0 | V10: =IFERROR(COUNTIFS(pds!C:C,"Pédiatrie",#REF!,L10),0) -> 0 | W10: =IFERROR(COUNTIFS(pds!C:C,"Gastro-entérologie",#REF!,L10),0) -> 0 | X10: =IFERROR(COUNTIFS(pds!C:C,"Gastro-entérologie",#REF!,L10),0) -> 0
B11: PSY | C11: Psychiatrie | E11: =IFERROR(COUNTIFS(pds!C:C,"PSY",pds!AA:AA,">0"),0) -> 0 | F11: =IFERROR(SUMIFS(pds!AA:AA,pds!C:C,"PSY",pds!AA:AA,">0"),0) -> 0 | L11: TOTAL NB PDS | M11: =SUM(M6:M10) -> 0 | N11: =SUM(N6:N10) -> 0 | O11: =SUM(O6:O10) -> 0 | P11: =SUM(P6:P10) -> 0 | Q11: =SUM(Q6:Q10) -> 0 | R11: =SUM(R6:R10) -> 0 | S11: =SUM(S6:S10) -> 0 | T11: =SUM(T6:T10) -> 0 | ... X11: =SUM(X6:X10) -> 0
B12: NEURO | C12: Neurologie | E12: =IFERROR(COUNTIFS(pds!C:C,"NE",pds!AA:AA,">0"),0) -> 0 | F12: =IFERROR(SUMIFS(pds!AA:AA,pds!C:C,"NE",pds!AA:AA,">0"),0) -> 0 | L12: TOTAL CONTACTS | M12: {=SUMPRODUCT(($L$6:$L$10)*(M6:M10))} -> 0 | N12: {=SUMPRODUCT(($L$6:$L$10)*(N6:N10))} -> 0 | O12: {=SUMPRODUCT(($L$6:$L$10)*(O6:O10))} -> 0 | P12: {=SUMPRODUCT(($L$6:$L$10)*(P6:P10))} -> 0 | Q12: {=SUMPRODUCT(($L$6:$L$10)*(Q6:Q10))} -> 0 | R12: {=SUMPRODUCT(($L$6:$L$10)*(R6:R10))} -> 0 | S12: {=SUMPRODUCT(($L$6:$L$10)*(S6:S10))} -> 0 | T12: {=SUMPRODUCT(($L$6:$L$10)*(T6:T10))} -> 0 | ... X12: {=SUMPRODUCT(($L$6:$L$10)*(X6:X10))} -> 0
B13: TOTAL | D13: =SUM(D4:D9) -> 1644 | E13: =SUM(E4:E9) -> 249 | F13: =SUM(F4:F12) -> 747 | G13: =SUM(G4:G12) -> 252 | H13: =SUM(H4:H12) -> 756 | I13: =IFERROR(E13/G13,0) -> 0.98809524 | J13: =IFERROR(F13/H13,0) -> 0.98809524
M14: NB PDS | N14: CONTACTS
D15: OBJECTIF DE 3 | L15: GRAND TOTAL C1 | M15: =M11+O11+Q11+S11+U11+W11+G10 -> 0 | N15: =M12+O12+Q12+S12+U12+W12+H10 -> 13
C16: VERIFICATION FREQUENCE MOYENNE ANNUELLE | D16: =IFERROR(F13/E13,0) -> 3 | L16: GRAND TOTAL C2 | M16: =N11+P11+R11+T11+V11+X11+G11 -> 0 | N16: =N12+P12+R12+T12+V12+X12+H10 -> 13
L19: TX ACTIVITE | M19: TOTAL CONTACT 2023 | N19: OBJECTIFS CONTACTS PDS + PH 2023 | O19: R/O
L20: =#VALUE! -> #VALUE! | M20: =F13+D28 -> #VALUE! | N20: =H13+F28 -> 945 | O20: =IFERROR(M20/N20,0) -> 0
D22: CIBLAGE PHARMACIE
C27: NB PH CIBLE | D27: NB CONTACTS | E27: OBJECTIF NB PH | F27: OBJECTIF NB CONTACTS | G27: R/O NB PH | H27: R/O CONTACTS
C28: =COUNTIFS(pharma #REF!,3) -> #VALUE! | D28: =C28*3 -> #VALUE! | E28: 63 | F28: 189 | G28: =IFERROR(C28/E28,0) -> 0 | H28: =IFERROR(D28/F28,0) -> 0

Sheet couleurs
A1: CIRCADIN | B1: #7E4E74 | C1: #FF790B | D1: #FFFFFF
A2: ULTRA LEVURE | B2: #4D2E74 | C2: #1FA374 | D2: #CC4A7B | E2: #F08C1B

Sheet formules
A1: OR($'pds'.$N2="NPAI";$'pds'.$N2="NRP")
A2: AND(DAY(N2)<>30;MONTH(N2)<>12;YEAR(N2)<>1899)

Sheet zones
A1: cp | B1: ville | C1: nom zone | D1: tarif
A2: 75007 | B2: Paris | C2: Paris 7e arr. | D2: 6
A3: 75008 | B3: Paris | C3: Paris 8e arr. | D3: 6
A4: 75015 | B4: Paris | C4: Paris 15e arr. | D4: 4
A5: 75016 | B5: Paris | C5: Paris 16e arr. | D5: 4
A6: 75017 | B6: Paris | C6: Paris 17e arr. | D6: 4
A7: 92200 | B7: Neuilly-sur-Seine | C7: Neuilly / S. | D7: 4
A8: 92300 | B8: Levallois-Perret | C8: Levallois P. | D8: 4
A9: 92100 | B9: Boulogne Billancourt | C9: Boulogne B. | D9: 4

Sheet adresses uniques
A1: etablissement | B1: adresse | C1: cp | D1: ville
A2: CAB MÉD | B2: 50 AVENUE VICTOR HUGO | C2: 75016 | D2: PARIS
A3: CAB MÉD R POINCARÉ | B3: 76 AVENUE RAYMOND POINCARE | C3: 75016 | D3: PARIS
A4: CAB MÉD TOUR-MAUBOURG | B4: 41 BOULEVARD DE LA TOUR MAUBOURG | C4: 75007 | D4: PARIS
A5: CDS JAQUES SENET | B5: 12 RUE ARMAND MOISANT | C5: 75015 | D5: PARIS
A6: CDS MEDIKSANTE | B6: 206 BOULEVARD PEREIRE | C6: 75017 | D6: PARIS
A7: CDS SOMED | B7: 17 BOULEVARD DE VAUGIRARD | C7: 75015 | D7: PARIS
A8: CDS ST-JACQUES | B8: 37 RUE DES VOLONTAIRES | C8: 75015 | D8: PARIS
A9: CLI AMBROISE PARÉ | B9: 26 BOULEVARD VICTOR HUGO | C9: 92200 | D9: NEUILLY-SUR-SEINE
A10: CLI BIZET | B10: 23 RUE GEORGES BIZET | C10: 75016 | D10: PARIS
A11: CLI DE L’ALMA | B11: 166 RUE DE L UNIVERSITE | C11: 75007 | D11: PARIS
A12: CLI DE LA MUETTE | B12: 46 48 RUE NICOLO | C12: 75016 | D12: PARIS
A13: CLI MED ET PED EDOUARD RIST | B13: 14 RUE BOILEAU | C13: 75016 | D13: PARIS
... A41: PMI | B41: 4 RUE VIGEE LEBRUN | C41: 75016 | D41: PARIS
B42: 102 RUE BOILEAU | C42: 75016 | D42: PARIS
B43: 104 RUE MICHEL ANGE | C43: 75016 | D43: PARIS
B44: 106 RUE JEAN DE LA FONTAINE | C44: 75016 | D44: PARIS
B45: 11 RUE DE LA SOURCE | C45: 75016 | D45: PARIS
B46: 11 RUE DES PERCHAMPS | C46: 75016 | D46: PARIS
B47: 11 RUE DU GENERAL NIOX | C47: 75016 | D47: PARIS
B48: 114 AVENUE MOZART | C48: 75016 | D48: PARIS
B49: 116 AVENUE DE VERSAILLES | C49: 75016 | D49: PARIS
B50: 119 RUE DE LA POMPE | C50: 75016 | D50: PARIS
B51: 13 AVENUE DU MARECHAL FRANCHET D ESPEREY | C51: 75016 | D51: PARIS
B52: 130 BOULEVARD EXELMANS | C52: 75016 | D52: PARIS
B53: 133 RUE MICHEL ANGE | C53: 75016 | D53: PARIS
... B999: 90 AVENUE CHARLES DE GAULLE | C999: 92200 | D999: NEUILLY-SUR-SEINE

Sheet Infos Flo
A1: GUIRGIS | B1: WAGRAM SANTÉ | C1: 66 RUE JOUFFRY D ‘ABBANS | D1: PE | E1: Ai laissé mes coordonnées sur place. La secrétaire doit me rappeler…. | F1: ME RAPELLE
A2: ROZENTAL | B2: WAGRAM SANTÉ | C2: 66 RUE JOUFFRY D ‘ABBANS | D2: PE
A3: ELOI | B3: WAGRAM SANTÉ | C3: 66 RUE JOUFFRY D ‘ABBANS | D3: PE
A4: GERARD | B4: WAGRAM SANTÉ | C4: 66 RUE JOUFFRY D ‘ABBANS | D4: PE
B5: COURCELLES MÉDICAL | C5: 97 RUE JOUFFROY D’ABBANS | D5: ÉSTHÉTIQUE
C6: AVENUE DE WAGRAM
A7: HAMOU PLOTKINE | C7: 133 BOULEVARD MALESHERBES | D7: GY | F7: RAPPELER
A8: HANAU CORINNE | F8: RAPPELER
A9: COHEN SCALI | F9: RAPPELER
A10: LUMBROSO | F10: RAPPELER
B11: CLINIQUE SAINTE THÉRÈSE | D11: 5 GY + SF | E11: PETIT : Ne crois pas aux probiotiques, va prescrire Physioflore Oral, Pelvitonic+ à pousser, Colpofix : pas d’étude prospectives DULMAN : Prescrit Gestarelle g/g3+, enchanté par Gestarelle Fertilité. Va prescrire Physioflore Orale pour remplacer ovule, ok pelvitonic+, Colpofix convaicu CHATEL MAJOULET COHEN + SF
A12: THEROND GERARD | D12: GY (FERTILITÉ) | F12: ME RAPPELLE
A13: ATTAR | D13: GE | F13: RDV 14/11/2023
B14: SOMED | C14: GARE MONTPARNASSE | F14: SUR PLACE
A15: TRABBIA | C15: RUE ROBERT DE FLERS | D15: GY | F15: MAIL cabinet.trabbia.15@gmail.com
A16: EL FALAH | C16: 7E | D16: GY | F16: RDV 26/09/23
A17: DOUCHET | C17: 17E | D17: GY | F17: RDV 03/10/23
A18: MEKKI | C18: 17E | D18: GY | F18: RAPPELER
A19: ZERWALA | C19: RUE MIOLLIS | D19: GY | E19: Nom inconnu Adresse correspond au centre médicosocial des sours de St Vincent de Paul | F19: 0
A20: HEYLER BOURY | C20: RUE BOISSIERE | D20: GY | E20: 01 40 67 71 95 TROUVÉ À LA FOIS SUR AMELI ET DANS VEEVA NON ATTRIBUÉ
A21: THELLIER
A22: MIMOUN | C22: A VENUE KLEBER | D22: GY
A23: MOULY | C23: A VENUE KLEBER | D23: GY
B24: CENTRE ARGENTINE | C24: 4 RUE BRUNEL | D24: GY
A25: MEGHIRA | B25: CEVENNES | C25: 15E | F25: NE RECOIS PAS LES LABOS
A26: BENZAQINE | C26: 16E | D26: GY
A27: ACKERMAN | C27: 16E | D27: GY
A28: KRIEF | C28: 16E | D28: GY
A29: CORNET
A30: DE LA FONTAINE
B31: MDS MARY JACOBI | C31: RUE DE VARIZE | D31: 5 MG / 1 SF | E31: CHEZAUD vc SCHILDT rpt ECLANCHER vc - nrp HADDAD prescrit UL, Alflorex et Circadin régulièrement LA TOUR DE MAREUIL concurrence ++ COMBASTET vc PAUWELS vc
A32: AMIRI | C32: RUE BALARD | D32: GE
A33: SPYCHALA | D33: MG
A34: MUSSUTO | D34: MG
A35: CONCQY | C35: RUE DU PIC DE BARETTE | D35: SF
A36: AZOULAY | B36: CEVENNES | D36: MG | F36: NE RECOIS PAS LES LABOS
A37: DOUARD | C37: AVENUE DE LA GRANDE ARMEE | D37: GY
